<?xml version="1.0"?>
<robot name="robot_arm" xmlns:xacro="http://www.ros.org/wiki/xacro">
    <xacro:arg name = "is_ignition" default = "true"/>
    <xacro:include filename = "$(find arm_urdf)/urdf/robot_gazebo.xacro"/>
    <xacro:include filename = "$(find arm_urdf)/urdf/robot_ros2_control.xacro"/>    
    <xacro:include filename = "common_properties.xacro"/>
    <xacro:macro name = "inertia" params = "mass">
        <inertial>
            <mass value="${mass}"/>
            <inertia ixy="0.0" ixx="1e-3" izz="1e-3" iyz="0.0" iyy="1e-3" ixz="0.0"/>
        </inertial>
    </xacro:macro>

    <link name="base_link">
        <xacro:inertia mass="1"/>
        <visual>
            <origin rpy="0 0 0" xyz="0 0 -0.18"/>
            <geometry>
                <mesh filename="package://arm_urdf/meshes/base.stl" scale="0.01 0.01 0.01"/>
            </geometry>
            <material name="blue"></material>
        </visual>

        <collision>
            <origin rpy="0 0 0" xyz="0 0 -0.18"/>
            <geometry>
                <mesh filename="package://arm_urdf/meshes/base.stl" scale="0.01 0.01 0.01"/>
            </geometry>
        </collision>
    </link>

    <link name="shoulder_link">
        <xacro:inertia mass="0.6"/>
        <visual>
            <origin rpy="0 0 0" xyz="0 0 -0.18"/>
            <geometry>
                <mesh filename="package://arm_urdf/meshes/robot_shoulder.stl" scale="0.01 0.01 0.01"/>
            </geometry>
            <material name="grey"></material>
        </visual>

        <collision>
            <origin rpy="0 0 0" xyz="0 0 -0.18"/>
            <geometry>
                <mesh filename="package://arm_urdf/meshes/robot_shoulder.stl" scale="0.01 0.01 0.01"/>
            </geometry>
        </collision>
    </link>

    <link name="arm1_link">
        <xacro:inertia mass="0.6"/>
        <visual>
            <origin rpy="0 0 0" xyz="-0.1 0 -1.08"/>
            <geometry>
                <mesh filename="package://arm_urdf/meshes/arm_1.stl" scale="0.01 0.01 0.01"/>
            </geometry>
            <material name="blue"></material>
        </visual>

        <collision>
            <origin rpy="0 0 0" xyz="-0.09 0 -1.08"/>
            <geometry>
                <mesh filename="package://arm_urdf/meshes/arm_1.stl" scale="0.01 0.01 0.01"/>
            </geometry>
        </collision>
    </link>

    <link name="arm2_link">
        <xacro:inertia mass="0.6"/>
        <visual>
            <origin rpy="0 0 0" xyz="-0.13 0 -2.34"/>
            <geometry>
                <mesh filename="package://arm_urdf/meshes/arm_2.stl" scale="0.01 0.01 0.01"/>
            </geometry>
            <material name="grey"></material>
        </visual>

        <collision>
            <origin rpy="0 0 0" xyz="-0.13 0 -2.34"/>
            <geometry>
                <mesh filename="package://arm_urdf/meshes/arm_2.stl" scale="0.01 0.01 0.01"/>
            </geometry>
        </collision>
    </link>

    <link name="arm3_link">
        <xacro:inertia mass="0.2"/>
        <visual>
            <origin rpy="0 0 0" xyz="-0.19 0.13 -3.23"/>
            <geometry>
                <mesh filename="package://arm_urdf/meshes/arm_3.stl" scale="0.01 0.01 0.01"/>
            </geometry>
            <material name="blue"></material>
        </visual>

        <collision>
            <origin rpy="0 0 0" xyz="-0.19 0.13 -3.23"/>
            <geometry>
                <mesh filename="package://arm_urdf/meshes/arm_3.stl" scale="0.01 0.01 0.01"/>
            </geometry>
        </collision>
    </link>

    <link name="gripper_base_link">
        <xacro:inertia mass="0.2"/>
        <visual>
            <origin rpy="0 0 0" xyz="-0.19 -0.05 -3.49"/>
            <geometry>
                <mesh filename="package://arm_urdf/meshes/gripper_base.stl" scale="0.01 0.01 0.01"/>
            </geometry>
            <material name="grey"></material>
        </visual>

        <collision>
            <origin rpy="0 0 0" xyz="-0.19 -0.05 -3.49"/>
            <geometry>
                <mesh filename="package://arm_urdf/meshes/gripper_base.stl" scale="0.01 0.01 0.01"/>
            </geometry>
        </collision>
    </link>

    <link name="gripper_link_left">
        <xacro:inertia mass="0.05"/>
        <visual>
            <origin rpy="0 0 0" xyz="-0.33 0.14 -3.87"/>
            <geometry>
                <mesh filename="package://arm_urdf/meshes/gripper_link.stl" scale="0.01 0.01 0.01"/>
            </geometry>
            <material name="blue"></material>
        </visual>

        <collision>
            <origin rpy="0 0 0" xyz="-0.33 0.14 -3.87"/>
            <geometry>
                <mesh filename="package://arm_urdf/meshes/gripper_link.stl" scale="0.01 0.01 0.01"/>
            </geometry>
        </collision>
    </link>

    <link name="gripper_link_right">
        <xacro:inertia mass="0.05"/>
        <visual>
            <origin rpy="0 0 0" xyz="-0.33 -0.13 -3.87"/>
            <geometry>
                <mesh filename="package://arm_urdf/meshes/gripper_link_2.stl" scale="0.01 0.01 0.01"/>
            </geometry>
            <material name="blue"></material>
        </visual>

        <collision>
            <origin rpy="0 0 0" xyz="-0.33 -0.13 -3.87"/>
            <geometry>
                <mesh filename="package://arm_urdf/meshes/gripper_link_2.stl" scale="0.01 0.01 0.01"/>
            </geometry>
        </collision>
    </link>

    <joint name="base_shoulder_joint" type="revolute">
        <parent link="base_link"/>
        <child link="shoulder_link"/>
        <origin xyz="0 0 0" rpy="0 0 0"/>
        <axis xyz="0 0 1"/>
        <limit lower="-${pi/2}" upper="${pi/2}" effort="10" velocity="10"/>
    </joint>

    <joint name="shoulder_arm1_joint" type="revolute">
        <parent link="shoulder_link"/>
        <child link="arm1_link"/>
        <origin xyz="0.09 0 0.9" rpy="0 0 0"/>
        <axis xyz="0 1 0"/>
        <limit lower="-${pi/2}" upper="${pi/2}" effort="10" velocity="10"/>
    </joint>

    <joint name="arm1_arm2_joint" type="revolute">
        <parent link="arm1_link"/>
        <child link="arm2_link"/>
        <origin xyz="0.05 0 1.26" rpy="0 0 0"/>
        <axis xyz="0 1 0"/>
        <limit lower="-${pi/2}" upper="${pi/2}" effort="10" velocity="10"/>
    </joint>

    <joint name="arm2_arm3_joint" type="revolute">
        <parent link="arm2_link"/>
        <child link="arm3_link"/>
        <origin xyz="0.06 -0.134 0.89" rpy="0 0 0"/>
        <axis xyz="0 0 1"/>
        <limit lower="-${pi/2}" upper="${pi/2}" effort="10" velocity="10"/>
    </joint>

    <joint name="arm3_gripper_base_joint" type="revolute">
        <parent link="arm3_link"/>
        <child link="gripper_base_link"/>
        <origin xyz="0 0.18 0.253" rpy="0 0 0"/>
        <axis xyz="0 1 0"/>
        <limit lower="-${pi/2}" upper="${pi/2}" effort="10" velocity="10"/>
    </joint>

    <joint name="gripper_base_left_joint" type="revolute">
        <parent link="gripper_base_link"/>
        <child link="gripper_link_left"/>
        <origin xyz="0.15 -0.19 0.38" rpy="0 0 0"/>
        <axis xyz="1 0 0"/>
        <limit lower="0" upper="${pi/2}" effort="10" velocity="10"/>
    </joint>

    <joint name="gripper_base_right_joint" type="revolute">
        <parent link="gripper_base_link"/>
        <child link="gripper_link_right"/>
        <origin xyz="0.15 0.08 0.38" rpy="0 0 0"/>
        <axis xyz="1 0 0"/>
        <mimic joint = "gripper_base_left_joint" multiplier= "-1.0"></mimic>
        <limit lower="-${pi/2}" upper="0" effort="10" velocity="10"/>
    </joint>

</robot>