<?xml version = "1.0"?>

<robot xmlns:xacro="http://www.ros.org/wiki/xacro" name = "my_arm">
    <xacro:include filename = "common_properties.xacro"/>

    <link name = "base_link">
        <visual>
            <geometry>
                <mesh filename = "package://arm_urdf/meshes/Base.stl" scale = "0.001 0.001 0.001"/> 
            </geometry>
            <origin rpy = "1.57 0 0" xyz = "-0.0055 -0.011 0"/>
            <material name ="blue"/>
        </visual>

        <collision>
            <origin rpy = "0 0 0" xyz = "0 0 0"/>
            <geometry>
                <mesh filename = "package://arm_urdf/meshes/Base.stl" scale = "0.001 0.001 0.001"/> 
            </geometry>              
        </collision>
    </link>
    <link name = "shoulder">
        <visual>
            <geometry>
                <mesh filename = "package://arm_urdf/meshes/Shoulder.stl" scale = "0.001 0.001 0.001"/> 
            </geometry>
            <origin rpy = "1.57 0 0" xyz = "0 0 0"/>
            <material name ="blue"/>
        </visual>

        <collision>
            <origin rpy = "0 0 0" xyz = "0 0 0"/>
            <geometry>
                <mesh filename = "package://arm_urdf/meshes/Shoulder.stl" scale = "0.001 0.001 0.001"/> 
            </geometry>              
        </collision>
    </link>

    <joint name = "base_first_joint" type = "revolute">
        <parent link = "base_link"/>
        <child link = "shoulder"/>
        <origin xyz = "0 0 0" rpy = "-0.0015 0 0"/>
        <axis xyz = "0 0 1"/>
        <limit lower = "-${pi/2}" upper = "${pi/2}" effort = "100" velocity = "100"/>
    </joint>

</robot>