<?xml version = "1.0"?>

<robot xmlns:xacro="http://www.ros.org/wiki/xacro" name = "my_robot">
    <xacro:include filename = "common_properties.xacro"/>
    <xacro:include filename = "robot_base.xacro"/>

    <link name = "first_link">
        <visual>
            <geometry>
                <cylinder radius = "0.05" length = "0.2"/>
            </geometry>
            <origin xyz = "0 0 0" rpy = "0 0 0"/>
            <material name ="blue"/>
        </visual>
    </link>

    <link name = "sphere_joint">
        <visual>
            <geometry>
                <sphere radius = "0.05"/>
            </geometry>
            <origin xyz = "0 0 0" rpy = "0 0 0"/>
            <material name ="blue"/>
        </visual>
    </link>

    <link name = "second_link">
        <visual>
            <geometry>
                <box size = "0.075 0.075 0.2"/>
            </geometry>
            <origin xyz = "0 0 -0.15" rpy = "0 0 0"/>
            <material name ="blue"/>
        </visual>
    </link>

    <xacro:macro name= "gripper_sphere_joint" params = "prefix">
    <link name = "gripper_sphere_${prefix}_joint">
        <visual>
            <geometry>
                <sphere radius = "0.015"/>
            </geometry>
            <origin xyz = "0 0 0" rpy = "0 0 0"/>
            <material name ="blue"/>
        </visual>
    </link>
    </xacro:macro>
    <xacro:gripper_sphere_joint prefix= "right"/>
    <xacro:gripper_sphere_joint prefix= "left"/>

    <xacro:macro name = "gripper_link" params = "prefix">
    <link name = "gripper_${prefix}_link">
        <visual>
            <geometry>
                <box size = "0.01 0.01 0.1"/>
            </geometry>
            <origin xyz = "0 0 -0.065" rpy = "0 0 0"/>
            <material name ="blue"/>
        </visual>
    </link>
    </xacro:macro>
    <xacro:gripper_link prefix = "right"/>
    <xacro:gripper_link prefix = "left"/>

    <xacro:macro name = "gripper_grip" params = "prefix">
    <link name = "gripper_${prefix}_grip">
        <visual>
            <geometry>
                <box size = "0.02 0.01 0.01"/>
            </geometry>
            <origin xyz = "0 0 -0.065" rpy = "0 0 0"/>
            <material name ="blue"/>
        </visual>
    </link>
    </xacro:macro>
    <xacro:gripper_grip prefix = "right"/>
    <xacro:gripper_grip prefix = "left"/>

    <joint name = "base_first_joint" type = "revolute">
        <parent link = "base_link"/>
        <child link = "first_link"/>
        <origin xyz = "0.25 0 0.4" rpy = "0 0 0"/>
        <axis xyz = "0 0 1"/>
        <limit lower = "-${pi/2}" upper = "${pi/2}" effort = "100" velocity = "100"/>
    </joint>

    <joint name = "base_sphere_joint" type = "fixed">
        <parent link = "first_link"/>
        <child link = "sphere_joint"/>
        <origin xyz = "0 0 0.1" rpy = "${pi/2} 0 0"/>
        <axis xyz = "1 0 0"/>
    </joint>

    <joint name = "base_second_joint" type = "revolute">
        <parent link = "sphere_joint"/>
        <child link = "second_link"/>
        <origin xyz = "0 0 0" rpy = "${pi/2} 0 0"/>
        <axis xyz = "1 0 0"/>
        <limit lower = "-${pi/2}" upper = "${pi/2}" effort = "100" velocity = "100"/>
    </joint>

    <joint name = "gripper_second_sphere_right_joint" type = "fixed">
        <parent link = "second_link"/>
        <child link = "gripper_sphere_right_joint"/>
        <origin xyz = "0.021 0 -0.25" rpy = "0 0 0"/>
        <axis xyz = "1 0 0"/>
    </joint>

    <joint name = "gripper_second_sphere_left_joint" type = "fixed">
        <parent link = "second_link"/>
        <child link = "gripper_sphere_left_joint"/>
        <origin xyz = "-0.021 0 -0.25" rpy = "0 0 0"/>
        <axis xyz = "1 0 0"/>
    </joint>

    <joint name = "gripper_second_left_joint" type = "revolute">
        <parent link = "gripper_sphere_left_joint"/>
        <child link = "gripper_left_link"/>
        <origin xyz = "0 0 0" rpy = "0 0 0"/>
        <axis xyz = "0 1 0"/>
        <limit lower = "0" upper = "1.1" effort = "100" velocity = "100"/>
    </joint>

    <joint name = "gripper_second_right_joint" type = "revolute">
        <parent link = "gripper_sphere_right_joint"/>
        <child link = "gripper_right_link"/>
        <origin xyz = "0 0 0" rpy = "0 0 0"/>
        <axis xyz = "0 1 0"/>
        <limit lower = "-1.1" upper = "0" effort = "100" velocity = "100"/>
    </joint>

    <joint name = "gripper_left_grip_joint" type = "fixed">
        <parent link = "gripper_left_link"/>
        <child link = "gripper_left_grip"/>
        <origin xyz = "0.01 0 -0.045" rpy = "0 0 0"/>
        <axis xyz = "1 0 0"/>
    </joint>

    <joint name = "gripper_right_grip_joint" type = "fixed">
        <parent link = "gripper_right_link"/>
        <child link = "gripper_right_grip"/>
        <origin xyz = "-0.01 0 -0.045" rpy = "0 0 0"/>
        <axis xyz = "1 0 0"/>
    </joint>

</robot>
